Workbook

Sheet Veri
C8: USD | D8: 3.75
C9: Kar | D9: 0
C10: STANDART
B11: Standart | C11: MEKKE ODA FİYATI | D11: =+$F$2 -> 0
B12: Standart | C12: MEKKE YEMEK | D12: 40
B13: Standart | C13: MEDİNE ODA FİYATI | D13: 500
B14: Standart | C14: MEDİNE YEMEK | D14: =+$F$5 -> 0
B15: Standart | C15: CİDDE- MEKKE OTEL YOL | D15: 200
B16: Standart | C16: MEKKE-MEDİNE TRANSFER | D16: 500
B17: Standart | C17: MEDİNE HAVAALANI | D17: 100
B18: Standart | C18: CİDDE- MEKKE OTEL YOL-BÜYÜK | D18: 800
B19: Standart | C19: MEKKE-MEDİNE TRANSFER-BÜYÜK | D19: 800
B20: Standart | C20: MEDİNE HAVAALANI-BÜYÜK | D20: 800
B21: Standart | C21: UÇAK BİLETİ | D21: 1500
B22: Standart | C22: VİZE + vergi | D22: 500
B23: Standart | C23: SİGORTA | D23: 125
B24: Standart | C24: ÇANTA | D24: 25
B25: Standart | C25: FULAR/eşarp | D25: 15
B26: Standart | C26: FRİ/GÖREVLİ | D26: 45
... B30: Standart | C30: ŞUBE GİDERLERİ | D30: 0
C31: EKONOMİK
B32: Ekonomik | C32: MEKKE ODA FİYATI | D32: 55
B33: Ekonomik | C33: MEKKE YEMEK | D33: 35
B34: Ekonomik | C34: MEDİNE ODA FİYATI | D34: 400
B35: Ekonomik | C35: MEDİNE YEMEK | D35: 45
B36: Ekonomik | C36: CİDDE- MEKKE OTEL YOL | D36: 200
B37: Ekonomik | C37: MEKKE-MEDİNE TRANSFER | D37: 500
B38: Ekonomik | C38: MEDİNE HAVAALANI | D38: 100
B39: Ekonomik | C39: CİDDE- MEKKE OTEL YOL-BÜYÜK | D39: 800
B40: Ekonomik | C40: MEKKE-MEDİNE TRANSFER-BÜYÜK | D40: 800
B41: Ekonomik | C41: MEDİNE HAVAALANI-BÜYÜK | D41: 800
B42: Ekonomik | C42: UÇAK BİLETİ | D42: 1500
B43: Ekonomik | C43: VİZE + vergi | D43: 500
... B51: Ekonomik | C51: ŞUBE GİDERLERİ | D51: 0
C52: LÜXE
B53: Lüxe | C53: MEKKE ODA FİYATI | D53: 850
B54: Lüxe | C54: MEKKE YEMEK | D54: 75
B55: Lüxe | C55: MEDİNE ODA FİYATI | D55: 850
B56: Lüxe | C56: MEDİNE YEMEK | D56: 75
B57: Lüxe | C57: CİDDE- MEKKE OTEL YOL | D57: 300
...

Sheet Uygulama
B1: ÜMRE TEKLİF HESAPLAMA
B2: SEYAHAT TİPİ | C2: Lüxe | E2: KİŞİ BAŞI TEKLİF
B3: MEKKE ODA KAÇ KİŞİLİK | C3: 2 | D3: =SUMIFS(Veri!$D$11:$D$72,Veri!$B$11:$B$72,$C$2,Veri!$C$11:$C$72,Veri!$D$2) -> 0 | E3: {=IFERROR((($D$3/$C$3+$D$4)*$C$4+($D$5/$C$5+$D$6)*$C$6+SUM($D$7:$D$12)+SUM($D$15:$D$24))/Veri!$D$8*(1+Veri!$D$9),0)} -> 146.66667
B4: MEKKE GÜN SAYISI | C4: 7 | D4: =SUMIFS(Veri!$D$11:$D$72,Veri!$B$11:$B$72,$C$2,Veri!$C$11:$C$72,Veri!$D$3) -> 0
B5: MEDİNE ODA KAÇ KİŞİLİK | C5: 2 | D5: =SUMIFS(Veri!$D$11:$D$72,Veri!$B$11:$B$72,$C$2,Veri!$C$11:$C$72,Veri!$D$4) -> 0
B6: MEDİNE GÜN SAYISI | C6: 3 | D6: =SUMIFS(Veri!$D$11:$D$72,Veri!$B$11:$B$72,$C$2,Veri!$C$11:$C$72,Veri!$D$5) -> 0 | E6: SEÇİM ÖZETİ
B7: CİDDE- MEKKE OTEL YOL | C7: 2 | D7: =IFERROR(SUMIFS(Veri!$D$11:$D$72,Veri!$B$11:$B$72,$C$2,Veri!$C$11:$C$72,$B7)/$C7,0) -> 150 | E7: Paket | F7: =$C$2 -> Lüxe
B8: MEKKE-MEDİNE TRANSFER | C8: 2 | D8: =IFERROR(SUMIFS(Veri!$D$11:$D$72,Veri!$B$11:$B$72,$C$2,Veri!$C$11:$C$72,$B8)/$C8,0) -> 300 | E8: Mekke | F8: =$C$4&" gün / "&$C$3&" kişilik oda" -> 7 gün / 2 kişilik oda
B9: MEDİNE HAVAALANI | C9: 2 | D9: =IFERROR(SUMIFS(Veri!$D$11:$D$72,Veri!$B$11:$B$72,$C$2,Veri!$C$11:$C$72,$B9)/$C9,0) -> 100 | E9: Medine | F9: =$C$6&" gün / "&$C$5&" kişilik oda" -> 3 gün / 2 kişilik oda
B10: CİDDE- MEKKE OTEL YOL-BÜYÜK | C10: 0 | D10: =IFERROR(SUMIFS(Veri!$D$11:$D$72,Veri!$B$11:$B$72,$C$2,Veri!$C$11:$C$72,$B10)/$C10,0) -> 0 | E10: Toplam Gün | F10: =$C$4+$C$6 -> 10
B11: MEKKE-MEDİNE TRANSFER-BÜYÜK | C11: 0 | D11: =IFERROR(SUMIFS(Veri!$D$11:$D$72,Veri!$B$11:$B$72,$C$2,Veri!$C$11:$C$72,$B11)/$C11,0) -> 0
B12: MEDİNE HAVAALANI-BÜYÜK | C12: 0 | D12: =IFERROR(SUMIFS(Veri!$D$11:$D$72,Veri!$B$11:$B$72,$C$2,Veri!$C$11:$C$72,$B12)/$C12,0) -> 0
B14: SABİT GİDERLER | C14: DAHİL?
B15: UÇAK BİLETİ | C15: Hayır | D15: =IF($C15="Evet",SUMIFS(Veri!$D$11:$D$72,Veri!$B$11:$B$72,$C$2,Veri!$C$11:$C$72,$B15),0) -> 0
B16: VİZE + vergi | C16: Hayır | D16: =IF($C16="Evet",SUMIFS(Veri!$D$11:$D$72,Veri!$B$11:$B$72,$C$2,Veri!$C$11:$C$72,$B16),0) -> 0
B17: SİGORTA | C17: Hayır | D17: =IF($C17="Evet",SUMIFS(Veri!$D$11:$D$72,Veri!$B$11:$B$72,$C$2,Veri!$C$11:$C$72,$B17),0) -> 0
B18: ÇANTA | C18: Hayır | D18: =IF($C18="Evet",SUMIFS(Veri!$D$11:$D$72,Veri!$B$11:$B$72,$C$2,Veri!$C$11:$C$72,$B18),0) -> 0
B19: FULAR/eşarp | C19: Hayır | D19: =IF($C19="Evet",SUMIFS(Veri!$D$11:$D$72,Veri!$B$11:$B$72,$C$2,Veri!$C$11:$C$72,$B19),0) -> 0
B20: FRİ/GÖREVLİ | C20: Hayır | D20: =IF($C20="Evet",SUMIFS(Veri!$D$11:$D$72,Veri!$B$11:$B$72,$C$2,Veri!$C$11:$C$72,$B20),0) -> 0
B21: KOMİSYON | C21: Hayır | D21: =IF($C21="Evet",SUMIFS(Veri!$D$11:$D$72,Veri!$B$11:$B$72,$C$2,Veri!$C$11:$C$72,$B21),0) -> 0
B22: PRİM | C22: Hayır | D22: =IF($C22="Evet",SUMIFS(Veri!$D$11:$D$72,Veri!$B$11:$B$72,$C$2,Veri!$C$11:$C$72,$B22),0) -> 0
B23: ZEMZEM | C23: Hayır | D23: =IF($C23="Evet",SUMIFS(Veri!$D$11:$D$72,Veri!$B$11:$B$72,$C$2,Veri!$C$11:$C$72,$B23),0) -> 0
B24: ŞUBE GİDERLERİ | C24: Hayır | D24: =IF($C24="Evet",SUMIFS(Veri!$D$11:$D$72,Veri!$B$11:$B$72,$C$2,Veri!$C$11:$C$72,$B24),0) -> 0
B26: Kullanım: C sütunundaki açık renkli alanları seçin veya doldurun. Transferde 0 = kullanılmıyor; sayı girildiğinde araç maliyeti kişi sayısına bölünür. Teklif, kur ve kâr oranı dahil kişi başı USD satış fiyatıdır.
